2025-07-24 18:03:43,772 | INFO | FastAPI app initialized.
2025-07-24 18:03:43,772 | INFO | FastAPI app initialized.
2025-07-24 18:03:43,886 | INFO | Model loaded successfully from C:\Users\kamal\PycharmProjects\PythonProject8\app\data\model.json
2025-07-24 18:03:59,134 | INFO | FastAPI app initialized.
2025-07-24 18:03:59,157 | INFO | Model loaded successfully from C:\Users\kamal\PycharmProjects\PythonProject8\app\data\model.json
2025-07-24 18:04:05,229 | INFO | Root endpoint accessed.
2025-07-24 18:04:49,982 | INFO | Received prediction request: {"bill_length_mm":0.0,"bill_depth_mm":0.0,"flipper_length_mm":0.0,"body_mass_g":0.0,"year":0,"sex":"male","island":"Torgersen"}
2025-07-24 18:04:50,004 | ERROR | Prediction failed due to error: feature_names mismatch: ['bill_length_mm', 'bill_depth_mm', 'flipper_length_mm', 'body_mass_g', 'sex_Male', 'island_Dream', 'island_Torgersen'] ['bill_length_mm', 'bill_depth_mm', 'flipper_length_mm', 'body_mass_g', 'year', 'sex_female', 'sex_male', 'island_Biscoe', 'island_Dream', 'island_Torgersen']
expected sex_Male in input data
training data did not have the following fields: sex_male, island_Biscoe, sex_female, year
Traceback (most recent call last):
  File "C:\Users\kamal\PycharmProjects\PythonProject8\app\main.py", line 94, in predict_penguin
    prediction = model.predict(input_data)[0]
  File "C:\Users\kamal\PycharmProjects\PythonProject2\.venv\lib\site-packages\xgboost\core.py", line 729, in inner_f
    return func(**kwargs)
  File "C:\Users\kamal\PycharmProjects\PythonProject2\.venv\lib\site-packages\xgboost\sklearn.py", line 1718, in predict
    class_probs = super().predict(
  File "C:\Users\kamal\PycharmProjects\PythonProject2\.venv\lib\site-packages\xgboost\core.py", line 729, in inner_f
    return func(**kwargs)
  File "C:\Users\kamal\PycharmProjects\PythonProject2\.venv\lib\site-packages\xgboost\sklearn.py", line 1327, in predict
    predts = self.get_booster().inplace_predict(
  File "C:\Users\kamal\PycharmProjects\PythonProject2\.venv\lib\site-packages\xgboost\core.py", line 729, in inner_f
    return func(**kwargs)
  File "C:\Users\kamal\PycharmProjects\PythonProject2\.venv\lib\site-packages\xgboost\core.py", line 2667, in inplace_predict
    self._validate_features(fns)
  File "C:\Users\kamal\PycharmProjects\PythonProject2\.venv\lib\site-packages\xgboost\core.py", line 3243, in _validate_features
    raise ValueError(msg.format(self.feature_names, feature_names))
ValueError: feature_names mismatch: ['bill_length_mm', 'bill_depth_mm', 'flipper_length_mm', 'body_mass_g', 'sex_Male', 'island_Dream', 'island_Torgersen'] ['bill_length_mm', 'bill_depth_mm', 'flipper_length_mm', 'body_mass_g', 'year', 'sex_female', 'sex_male', 'island_Biscoe', 'island_Dream', 'island_Torgersen']
expected sex_Male in input data
training data did not have the following fields: sex_male, island_Biscoe, sex_female, year
2025-07-24 18:04:51,475 | INFO | Received prediction request: {"bill_length_mm":0.0,"bill_depth_mm":0.0,"flipper_length_mm":0.0,"body_mass_g":0.0,"year":0,"sex":"male","island":"Torgersen"}
2025-07-24 18:04:51,478 | ERROR | Prediction failed due to error: feature_names mismatch: ['bill_length_mm', 'bill_depth_mm', 'flipper_length_mm', 'body_mass_g', 'sex_Male', 'island_Dream', 'island_Torgersen'] ['bill_length_mm', 'bill_depth_mm', 'flipper_length_mm', 'body_mass_g', 'year', 'sex_female', 'sex_male', 'island_Biscoe', 'island_Dream', 'island_Torgersen']
expected sex_Male in input data
training data did not have the following fields: sex_male, island_Biscoe, sex_female, year
Traceback (most recent call last):
  File "C:\Users\kamal\PycharmProjects\PythonProject8\app\main.py", line 94, in predict_penguin
    prediction = model.predict(input_data)[0]
  File "C:\Users\kamal\PycharmProjects\PythonProject2\.venv\lib\site-packages\xgboost\core.py", line 729, in inner_f
    return func(**kwargs)
  File "C:\Users\kamal\PycharmProjects\PythonProject2\.venv\lib\site-packages\xgboost\sklearn.py", line 1718, in predict
    class_probs = super().predict(
  File "C:\Users\kamal\PycharmProjects\PythonProject2\.venv\lib\site-packages\xgboost\core.py", line 729, in inner_f
    return func(**kwargs)
  File "C:\Users\kamal\PycharmProjects\PythonProject2\.venv\lib\site-packages\xgboost\sklearn.py", line 1327, in predict
    predts = self.get_booster().inplace_predict(
  File "C:\Users\kamal\PycharmProjects\PythonProject2\.venv\lib\site-packages\xgboost\core.py", line 729, in inner_f
    return func(**kwargs)
  File "C:\Users\kamal\PycharmProjects\PythonProject2\.venv\lib\site-packages\xgboost\core.py", line 2667, in inplace_predict
    self._validate_features(fns)
  File "C:\Users\kamal\PycharmProjects\PythonProject2\.venv\lib\site-packages\xgboost\core.py", line 3243, in _validate_features
    raise ValueError(msg.format(self.feature_names, feature_names))
ValueError: feature_names mismatch: ['bill_length_mm', 'bill_depth_mm', 'flipper_length_mm', 'body_mass_g', 'sex_Male', 'island_Dream', 'island_Torgersen'] ['bill_length_mm', 'bill_depth_mm', 'flipper_length_mm', 'body_mass_g', 'year', 'sex_female', 'sex_male', 'island_Biscoe', 'island_Dream', 'island_Torgersen']
expected sex_Male in input data
training data did not have the following fields: sex_male, island_Biscoe, sex_female, year
2025-07-24 18:13:09,295 | INFO | FastAPI app initialized.
2025-07-24 18:13:09,319 | INFO | Model loaded successfully from C:\Users\kamal\PycharmProjects\PythonProject8\app\data\model.json
2025-07-24 18:17:19,001 | INFO | FastAPI app initialized.
2025-07-24 18:17:19,021 | INFO | Model loaded successfully from C:\Users\kamal\PycharmProjects\PythonProject8\app\data\model.json
2025-07-24 18:17:21,458 | INFO | Root endpoint accessed.
2025-07-24 18:36:12,689 | INFO | FastAPI app initialized.
2025-07-24 18:36:12,828 | INFO | Model loaded successfully from C:\Users\kamal\PycharmProjects\PythonProject8\app\data\model.json
2025-07-24 18:36:13,029 | INFO | Root endpoint accessed.
2025-07-24 20:21:11,200 | INFO | FastAPI app initialized.
2025-07-24 20:21:11,276 | INFO | Model loaded successfully from C:\Users\kamal\PycharmProjects\PythonProject8\app\data\model.json
2025-07-24 20:21:11,401 | INFO | Root endpoint accessed.
2025-07-24 20:22:09,626 | INFO | Received prediction request: {"bill_length_mm":0.0,"bill_depth_mm":0.0,"flipper_length_mm":0.0,"body_mass_g":0.0,"year":0,"sex":"female","island":"Torgersen"}
2025-07-24 20:22:09,686 | ERROR | Prediction failed due to error: feature_names mismatch: ['bill_length_mm', 'bill_depth_mm', 'flipper_length_mm', 'body_mass_g', 'sex_Male', 'island_Dream', 'island_Torgersen'] ['bill_length_mm', 'bill_depth_mm', 'flipper_length_mm', 'body_mass_g', 'year', 'sex_female', 'sex_male', 'island_Biscoe', 'island_Dream', 'island_Torgersen']
expected sex_Male in input data
training data did not have the following fields: sex_male, sex_female, year, island_Biscoe
Traceback (most recent call last):
  File "C:\Users\kamal\PycharmProjects\PythonProject8\app\main.py", line 85, in predict_penguin
    prediction = model.predict(input_data)[0]
  File "C:\Users\kamal\PycharmProjects\PythonProject2\.venv\lib\site-packages\xgboost\core.py", line 729, in inner_f
    return func(**kwargs)
  File "C:\Users\kamal\PycharmProjects\PythonProject2\.venv\lib\site-packages\xgboost\sklearn.py", line 1718, in predict
    class_probs = super().predict(
  File "C:\Users\kamal\PycharmProjects\PythonProject2\.venv\lib\site-packages\xgboost\core.py", line 729, in inner_f
    return func(**kwargs)
  File "C:\Users\kamal\PycharmProjects\PythonProject2\.venv\lib\site-packages\xgboost\sklearn.py", line 1327, in predict
    predts = self.get_booster().inplace_predict(
  File "C:\Users\kamal\PycharmProjects\PythonProject2\.venv\lib\site-packages\xgboost\core.py", line 729, in inner_f
    return func(**kwargs)
  File "C:\Users\kamal\PycharmProjects\PythonProject2\.venv\lib\site-packages\xgboost\core.py", line 2667, in inplace_predict
    self._validate_features(fns)
  File "C:\Users\kamal\PycharmProjects\PythonProject2\.venv\lib\site-packages\xgboost\core.py", line 3243, in _validate_features
    raise ValueError(msg.format(self.feature_names, feature_names))
ValueError: feature_names mismatch: ['bill_length_mm', 'bill_depth_mm', 'flipper_length_mm', 'body_mass_g', 'sex_Male', 'island_Dream', 'island_Torgersen'] ['bill_length_mm', 'bill_depth_mm', 'flipper_length_mm', 'body_mass_g', 'year', 'sex_female', 'sex_male', 'island_Biscoe', 'island_Dream', 'island_Torgersen']
expected sex_Male in input data
training data did not have the following fields: sex_male, sex_female, year, island_Biscoe
2025-07-24 20:22:13,340 | INFO | Received prediction request: {"bill_length_mm":0.0,"bill_depth_mm":0.0,"flipper_length_mm":0.0,"body_mass_g":0.0,"year":0,"sex":"female","island":"Torgersen"}
2025-07-24 20:22:13,359 | ERROR | Prediction failed due to error: feature_names mismatch: ['bill_length_mm', 'bill_depth_mm', 'flipper_length_mm', 'body_mass_g', 'sex_Male', 'island_Dream', 'island_Torgersen'] ['bill_length_mm', 'bill_depth_mm', 'flipper_length_mm', 'body_mass_g', 'year', 'sex_female', 'sex_male', 'island_Biscoe', 'island_Dream', 'island_Torgersen']
expected sex_Male in input data
training data did not have the following fields: sex_male, sex_female, year, island_Biscoe
Traceback (most recent call last):
  File "C:\Users\kamal\PycharmProjects\PythonProject8\app\main.py", line 85, in predict_penguin
    prediction = model.predict(input_data)[0]
  File "C:\Users\kamal\PycharmProjects\PythonProject2\.venv\lib\site-packages\xgboost\core.py", line 729, in inner_f
    return func(**kwargs)
  File "C:\Users\kamal\PycharmProjects\PythonProject2\.venv\lib\site-packages\xgboost\sklearn.py", line 1718, in predict
    class_probs = super().predict(
  File "C:\Users\kamal\PycharmProjects\PythonProject2\.venv\lib\site-packages\xgboost\core.py", line 729, in inner_f
    return func(**kwargs)
  File "C:\Users\kamal\PycharmProjects\PythonProject2\.venv\lib\site-packages\xgboost\sklearn.py", line 1327, in predict
    predts = self.get_booster().inplace_predict(
  File "C:\Users\kamal\PycharmProjects\PythonProject2\.venv\lib\site-packages\xgboost\core.py", line 729, in inner_f
    return func(**kwargs)
  File "C:\Users\kamal\PycharmProjects\PythonProject2\.venv\lib\site-packages\xgboost\core.py", line 2667, in inplace_predict
    self._validate_features(fns)
  File "C:\Users\kamal\PycharmProjects\PythonProject2\.venv\lib\site-packages\xgboost\core.py", line 3243, in _validate_features
    raise ValueError(msg.format(self.feature_names, feature_names))
ValueError: feature_names mismatch: ['bill_length_mm', 'bill_depth_mm', 'flipper_length_mm', 'body_mass_g', 'sex_Male', 'island_Dream', 'island_Torgersen'] ['bill_length_mm', 'bill_depth_mm', 'flipper_length_mm', 'body_mass_g', 'year', 'sex_female', 'sex_male', 'island_Biscoe', 'island_Dream', 'island_Torgersen']
expected sex_Male in input data
training data did not have the following fields: sex_male, sex_female, year, island_Biscoe
2025-08-06 00:27:11,904 | INFO | FastAPI app initialized.
2025-08-06 00:27:12,026 | INFO | Model loaded successfully from C:\Users\kamal\PycharmProjects\PythonProject8\app\data\model.json
2025-08-06 00:33:00,570 | INFO | FastAPI app initialized.
2025-08-06 00:33:00,597 | INFO | Model loaded successfully from C:\Users\kamal\PycharmProjects\PythonProject8\app\data\model.json
2025-08-06 00:35:19,432 | INFO | FastAPI app initialized.
2025-08-06 00:35:19,452 | INFO | Model loaded successfully from C:\Users\kamal\PycharmProjects\PythonProject8\app\data\model.json
2025-08-06 12:42:00,615 | INFO | FastAPI app initialized.
2025-08-06 12:42:00,740 | INFO | Model loaded successfully from C:\Users\kamal\PycharmProjects\PythonProject8\app\data\model.json
2025-08-06 12:42:08,354 | INFO | FastAPI app initialized.
2025-08-06 12:42:08,373 | INFO | Model loaded successfully from C:\Users\kamal\PycharmProjects\PythonProject8\app\data\model.json
2025-08-07 17:03:55,178 | INFO | FastAPI app initialized.
2025-08-07 17:03:55,312 | INFO | Model loaded successfully from C:\Users\kamal\PycharmProjects\PythonProject8\apps\data\model.json
2025-08-07 17:05:22,504 | INFO | FastAPI app initialized.
2025-08-07 17:05:22,535 | INFO | Model loaded successfully from C:\Users\kamal\PycharmProjects\PythonProject8\apps\data\model.json
2025-08-07 17:50:30,317 | INFO | FastAPI app initialized.
2025-08-07 17:50:31,121 | INFO | Model downloaded from GCS: gs://penguine_bucket/model.json
2025-08-07 17:50:31,285 | INFO | Model loaded successfully.
2025-08-07 17:50:34,856 | INFO | Root endpoint accessed.
2025-08-07 17:50:43,921 | INFO | Root endpoint accessed.
2025-08-07 19:16:45,012 | INFO | FastAPI app initialized.
2025-08-07 19:16:45,436 | INFO | Model downloaded from GCS: gs://penguine_bucket/model.json
2025-08-07 19:16:45,609 | INFO | Model loaded successfully.
2025-08-08 20:00:41,196 | INFO | FastAPI app initialized.
2025-08-08 20:00:41,671 | INFO | Model downloaded from GCS: gs://penguine_bucket/model.json
2025-08-08 20:00:41,734 | INFO | Model loaded successfully.
2025-08-08 20:11:45,958 | INFO | Root endpoint accessed.
2025-08-09 16:26:02,787 | INFO | FastAPI app initialized.
2025-08-09 16:48:14,717 - ERROR - GCS_BUCKET_NAME or GCS_BLOB_NAME environment variables are missing.
2025-08-09 16:50:31,597 - INFO - Downloading model from GCS bucket 'penguine_bucket', blob 'model.json'.
2025-08-09 16:50:32,214 - INFO - Model downloaded successfully.
2025-08-09 16:50:32,401 - INFO - Model loaded successfully into memory.
2025-08-09 16:50:54,608 - INFO - Model already exists locally. Skipping download.
2025-08-09 16:50:54,627 - INFO - Model loaded successfully into memory.
2025-08-09 17:09:16,739 - ERROR - Prediction failed: DataFrame.dtypes for data must be int, float, bool or category. When categorical type is supplied, the experimental DMatrix parameter`enable_categorical` must be set to `True`.  Invalid columns:island: object, sex: object
2025-08-09 17:10:49,558 - INFO - Model already exists locally. Skipping download.
2025-08-09 17:10:49,578 - INFO - Model loaded successfully into memory.
2025-08-09 17:11:41,907 - ERROR - Prediction failed: DataFrame.dtypes for data must be int, float, bool or category. When categorical type is supplied, the experimental DMatrix parameter`enable_categorical` must be set to `True`.  Invalid columns:island: object, sex: object
2025-08-09 17:13:14,793 - ERROR - Prediction failed: DataFrame.dtypes for data must be int, float, bool or category. When categorical type is supplied, the experimental DMatrix parameter`enable_categorical` must be set to `True`.  Invalid columns:island: object, sex: object
2025-08-09 17:13:17,478 - ERROR - Prediction failed: DataFrame.dtypes for data must be int, float, bool or category. When categorical type is supplied, the experimental DMatrix parameter`enable_categorical` must be set to `True`.  Invalid columns:island: object, sex: object
2025-08-09 17:14:06,914 - ERROR - Prediction failed: DataFrame.dtypes for data must be int, float, bool or category. When categorical type is supplied, the experimental DMatrix parameter`enable_categorical` must be set to `True`.  Invalid columns:island: object, sex: object
2025-08-09 17:14:19,881 - ERROR - Prediction failed: DataFrame.dtypes for data must be int, float, bool or category. When categorical type is supplied, the experimental DMatrix parameter`enable_categorical` must be set to `True`.  Invalid columns:island: object, sex: object
2025-08-09 17:14:20,116 - ERROR - Prediction failed: DataFrame.dtypes for data must be int, float, bool or category. When categorical type is supplied, the experimental DMatrix parameter`enable_categorical` must be set to `True`.  Invalid columns:island: object, sex: object
2025-08-09 17:15:17,695 - ERROR - Prediction failed: DataFrame.dtypes for data must be int, float, bool or category. When categorical type is supplied, the experimental DMatrix parameter`enable_categorical` must be set to `True`.  Invalid columns:island: object, sex: object
2025-08-09 17:21:01,069 - INFO - Model already exists locally. Skipping download.
2025-08-09 17:21:01,084 - INFO - Model loaded successfully into memory.
2025-08-09 17:21:57,408 - INFO - Model already exists locally. Skipping download.
2025-08-09 17:21:57,425 - INFO - Model loaded successfully into memory.
2025-08-09 17:25:18,201 - INFO - Model already exists locally. Skipping download.
2025-08-09 17:25:18,223 - INFO - Model loaded successfully into memory.
2025-08-09 17:25:18,223 - INFO - Model loaded successfully into memory.
2025-08-09 17:25:42,022 - ERROR - Prediction failed: DataFrame.dtypes for data must be int, float, bool or category. When categorical type is supplied, the experimental DMatrix parameter`enable_categorical` must be set to `True`.  Invalid columns:island: object, sex: object
2025-08-09 17:29:45,705 - INFO - Model already exists locally. Skipping download.
2025-08-09 17:29:45,722 - INFO - Model loaded successfully into memory.
2025-08-09 17:33:28,009 - INFO - Model already exists locally. Skipping download.
2025-08-09 17:33:28,034 - INFO - Model loaded successfully into memory.
2025-08-09 17:33:28,075 - INFO - Model already exists locally. Skipping download.
2025-08-09 17:33:28,103 - INFO - Model loaded successfully into memory.
2025-08-09 17:33:35,148 - INFO - Model already exists locally. Skipping download.
2025-08-09 17:33:35,167 - INFO - Model loaded successfully into memory.
2025-08-09 17:36:12,146 - ERROR - Failed to load model during startup: download_model_from_gcs() takes 0 positional arguments but 3 were given
2025-08-09 17:36:54,068 - ERROR - Failed to load model during startup: download_model_from_gcs() takes 0 positional arguments but 3 were given
2025-08-09 17:41:13,857 - INFO - Model already exists locally. Skipping download.
2025-08-09 17:41:13,874 - INFO - Model loaded successfully into memory.
2025-08-09 17:41:13,874 - INFO - Model loaded successfully.
2025-08-09 18:13:23,958 - INFO - Model already exists locally. Skipping download.
2025-08-09 18:13:24,114 - INFO - Model loaded successfully into memory.
2025-08-09 18:13:24,114 - INFO - Model loaded successfully.
